<robot name="robot_0">
  <link name="link_0">
    <inertial>
      <origin xyz="2.935420835672152e-17 -4.802679704832299e-19 0.06928866854951908" rpy="0 0 0" />
      <mass value="1.2441267184811944" />
      <inertia ixx="0.002391387816043804" ixy="1.7382767274578743e-19" ixz="-2.190934733212692e-18" iyy="0.0023913878160438055" iyz="3.2790783402052577e-20" izz="0.0006651105339449277" />
    </inertial>
    <visual>
      <origin xyz="0 0 0" rpy="0 0 0" />
      <geometry>
        <mesh filename="dae/link_0.dae" />
      </geometry>
    </visual>
    <collision>
      <origin xyz="0 0 0" rpy="0 0 0" />
      <geometry>
        <mesh filename="dae/link_0.dae" />
      </geometry>
    </collision>
  </link>
  <joint name="joint_0" type="revolute">
    <parent link="link_0" />
    <child link="link_1" />
    <origin xyz="0.0 0.0 0.15060040806374903" rpy="0 0 0" />
    <axis xyz="0.0 1.2246467991473532e-16 -1.0" />
    <limit lower="-1.57" upper="1.57" effort="10" velocity="1" />
    <dynamics damping="0.17080564384062707" friction="0.2" />
  </joint>
  <transmission name="transmission_0">
    <type value="transmission_interface/SimpleTransmission" />
    <joint name="joint_0" />
    <hardwareInterface value="hardware_interface/JointPositionInterface" />
    <actuator name="actuator_0">
      <mechanicalReduction value="1.0" />
    </actuator>
  </transmission>
  <link name="link_1">
    <inertial>
      <origin xyz="-1.0304586194975333e-15 -7.003855091675599e-17 0.03649632580339787" rpy="0 0 0" />
      <mass value="0.6778197347156216" />
      <inertia ixx="0.0005500071305440658" ixy="-1.730153568111536e-19" ixz="6.026687106315384e-17" iyy="0.00043954953994201326" iyz="1.3172896976477785e-18" izz="0.0001770001023096993" />
    </inertial>
    <visual>
      <origin xyz="0 0 0" rpy="0 0 0" />
      <geometry>
        <mesh filename="dae/link_1.dae" />
      </geometry>
    </visual>
    <collision>
      <origin xyz="0 0 0" rpy="0 0 0" />
      <geometry>
        <mesh filename="dae/link_1.dae" />
      </geometry>
    </collision>
  </link>
  <joint name="joint_1" type="revolute">
    <parent link="link_1" />
    <child link="link_2" />
    <origin xyz="0.0 1.162242205380444e-18 0.08552209563037773" rpy="0 0 0" />
    <axis xyz="1.0 0.0 0.0" />
    <limit lower="-1.57" upper="1.57" effort="10" velocity="1" />
    <dynamics damping="0.23617057403387115" friction="0.2" />
  </joint>
  <transmission name="transmission_1">
    <type value="transmission_interface/SimpleTransmission" />
    <joint name="joint_1" />
    <hardwareInterface value="hardware_interface/JointPositionInterface" />
    <actuator name="actuator_1">
      <mechanicalReduction value="1.0" />
    </actuator>
  </transmission>
  <link name="link_2">
    <inertial>
      <origin xyz="-9.454935195314952e-16 6.108037849503882e-18 0.07064574143463034" rpy="0 0 0" />
      <mass value="0.8998486184421507" />
      <inertia ixx="0.002024582598736975" ixy="1.3392608691695268e-21" ixz="-5.4631769552047974e-17" iyy="0.0013085989011027187" iyz="7.854321055644016e-18" izz="0.0005505742210130269" />
    </inertial>
    <visual>
      <origin xyz="0 0 0" rpy="0 0 0" />
      <geometry>
        <mesh filename="dae/link_2.dae" />
      </geometry>
    </visual>
    <collision>
      <origin xyz="0 0 0" rpy="0 0 0" />
      <geometry>
        <mesh filename="dae/link_2.dae" />
      </geometry>
    </collision>
  </link>
  <joint name="joint_2" type="revolute">
    <parent link="link_2" />
    <child link="link_3" />
    <origin xyz="0.0 -6.373270656782302e-33 0.1431541622462753" rpy="0 0 0" />
    <axis xyz="1.0 0.0 0.0" />
    <limit lower="-1.57" upper="1.57" effort="10" velocity="1" />
    <dynamics damping="0.12273360982962957" friction="0.2" />
  </joint>
  <transmission name="transmission_2">
    <type value="transmission_interface/SimpleTransmission" />
    <joint name="joint_2" />
    <hardwareInterface value="hardware_interface/JointPositionInterface" />
    <actuator name="actuator_2">
      <mechanicalReduction value="1.0" />
    </actuator>
  </transmission>
  <link name="link_3">
    <inertial>
      <origin xyz="7.79245596137439e-18 6.659957221217795e-17 0.05615296385188076" rpy="0 0 0" />
      <mass value="0.6437237111776174" />
      <inertia ixx="0.0011823426417110795" ixy="5.60882585396594e-20" ixz="-7.056414462766389e-19" iyy="0.0012693990963665773" iyz="2.6546205317095627e-18" izz="0.00021715071577734068" />
    </inertial>
    <visual>
      <origin xyz="0 0 0" rpy="0 0 0" />
      <geometry>
        <mesh filename="dae/link_3.dae" />
      </geometry>
    </visual>
    <collision>
      <origin xyz="0 0 0" rpy="0 0 0" />
      <geometry>
        <mesh filename="dae/link_3.dae" />
      </geometry>
    </collision>
  </link>
  <joint name="joint_3" type="revolute">
    <parent link="link_3" />
    <child link="link_4" />
    <origin xyz="0.0 -5.098616525425841e-33 0.12997561673851582" rpy="0 0 0" />
    <axis xyz="0.0 1.2246467991473532e-16 -1.0" />
    <limit lower="-1.57" upper="1.57" effort="10" velocity="1" />
    <dynamics damping="0.0657249860987109" friction="0.2" />
  </joint>
  <transmission name="transmission_3">
    <type value="transmission_interface/SimpleTransmission" />
    <joint name="joint_3" />
    <hardwareInterface value="hardware_interface/JointPositionInterface" />
    <actuator name="actuator_3">
      <mechanicalReduction value="1.0" />
    </actuator>
  </transmission>
  <link name="link_4">
    <inertial>
      <origin xyz="-6.31267132798878e-16 -1.709182201042664e-17 0.04570710020266928" rpy="0 0 0" />
      <mass value="0.3656712598357016" />
      <inertia ixx="0.0004740492530131426" ixy="-6.457682397011806e-20" ixz="1.930349516788284e-17" iyy="0.00035424728205419155" iyz="3.1679233258707494e-19" izz="9.656655703336595e-05" />
    </inertial>
    <visual>
      <origin xyz="0 0 0" rpy="0 0 0" />
      <geometry>
        <mesh filename="dae/link_4.dae" />
      </geometry>
    </visual>
    <collision>
      <origin xyz="0 0 0" rpy="0 0 0" />
      <geometry>
        <mesh filename="dae/link_4.dae" />
      </geometry>
    </collision>
  </link>
  <joint name="joint_4" type="revolute">
    <parent link="link_4" />
    <child link="link_5" />
    <origin xyz="0.0 8.056619694786502e-19 0.10988266374810882" rpy="0 0 0" />
    <axis xyz="1.0 0.0 0.0" />
    <limit lower="-1.57" upper="1.57" effort="10" velocity="1" />
    <dynamics damping="0.2958087370572217" friction="0.2" />
  </joint>
  <transmission name="transmission_4">
    <type value="transmission_interface/SimpleTransmission" />
    <joint name="joint_4" />
    <hardwareInterface value="hardware_interface/JointPositionInterface" />
    <actuator name="actuator_4">
      <mechanicalReduction value="1.0" />
    </actuator>
  </transmission>
  <link name="link_5">
    <inertial>
      <origin xyz="-9.150777910453627e-16 4.0019058529047627e-17 0.037896529412225786" rpy="0 0 0" />
      <mass value="0.15804786199723994" />
      <inertia ixx="8.950535564011197e-05" ixy="4.638672177160435e-21" ixz="-7.325655860454155e-18" iyy="9.734217008458391e-05" iyz="2.1559711729215287e-19" izz="2.2331982060623777e-05" />
    </inertial>
    <visual>
      <origin xyz="0 0 0" rpy="0 0 0" />
      <geometry>
        <mesh filename="dae/link_5.dae" />
      </geometry>
    </visual>
    <collision>
      <origin xyz="0 0 0" rpy="0 0 0" />
      <geometry>
        <mesh filename="dae/link_5.dae" />
      </geometry>
    </collision>
  </link>
  <joint name="joint_5" type="revolute">
    <parent link="link_5" />
    <child link="link_6" />
    <origin xyz="0.0 -4.673731814973688e-33 0.09089072652707299" rpy="0 0 0" />
    <axis xyz="0.0 1.2246467991473532e-16 -1.0" />
    <limit lower="-1.57" upper="1.57" effort="10" velocity="1" />
    <dynamics damping="0.48553684839235184" friction="0.2" />
  </joint>
  <transmission name="transmission_5">
    <type value="transmission_interface/SimpleTransmission" />
    <joint name="joint_5" />
    <hardwareInterface value="hardware_interface/JointPositionInterface" />
    <actuator name="actuator_5">
      <mechanicalReduction value="1.0" />
    </actuator>
  </transmission>
  <link name="link_6">
    <inertial>
      <origin xyz="1.8608915585214185e-17 -2.0018838509845662e-19 0.032624310187138066" rpy="0 0 0" />
      <mass value="0.07231778993442711" />
      <inertia ixx="4.337196038585169e-05" ixy="-1.1923656333072725e-21" ixz="4.4421952438099055e-20" iyy="4.272469539716327e-05" iyz="3.2934285207654947e-22" izz="3.1832919928602075e-06" />
    </inertial>
    <visual>
      <origin xyz="0 0 0" rpy="0 0 0" />
      <geometry>
        <mesh filename="dae/link_6.dae" />
      </geometry>
    </visual>
    <collision>
      <origin xyz="0 0 0" rpy="0 0 0" />
      <geometry>
        <mesh filename="dae/link_6.dae" />
      </geometry>
    </collision>
  </link>
</robot>